<?xml version="1.0"?>
<!-- This URDF was automatically created by SolidWorks to URDF Exporter! Originally created by Stephen Brawner (brawner@gmail.com) 
     Commit Version: 1.6.0-4-g7f85cfe  Build Version: 1.6.7995.38578
     For more information, please see http://wiki.ros.org/sw_urdf_exporter -->


<robot xmlns:xacro="http://www.ros.org/wiki/xacro" name="arduinobot">

  <link name="world"/>

  <link
    name="base_link">
    <inertial>
      <origin
        xyz="1.764E-11 -9.0343E-12 0.026843"
        rpy="0 0 0" />
      <mass
        value="0.26486" />
      <inertia
        ixx="0.00022452"
        ixy="1.6313E-20"
        ixz="-7.3936E-16"
        iyy="0.00022452"
        iyz="1.9242E-16"
        izz="0.00042241" />
    </inertial>
    <visual>
      <origin
        xyz="0 0 0"
        rpy="0 0 0" />
      <geometry>
        <mesh
          filename="package://arduinobot_description/meshes/base_link.STL" scale="0.01 0.01 0.01"/>
      </geometry>
      <material
        name="">
        <color
          rgba="0.75294 0.75294 0.75294 1" />
      </material>
    </visual>
    <collision>
      <origin
        xyz="0 0 0"
        rpy="0 0 0" />
      <geometry>
        <mesh
          filename="package://arduinobot_description/meshes/base_link.STL" scale="0.01 0.01 0.01"/>
      </geometry>
    </collision>
  </link>
  <joint name="virtual_joint" type="fixed">
    <parent link="world"/>
    <child link="base_link"/>
    <origin xyz="0 0 0" rpy="0 0 0"/>
  </joint> 
  <link
    name="link_1">
    <inertial>
      <origin
        xyz="-0.0015612 -6.5919E-17 0.037769"
        rpy="0 0 0" />
      <mass
        value="0.12637" />
      <inertia
        ixx="0.00013841"
        ixy="-3.7232E-21"
        ixz="7.3657E-14"
        iyy="0.00028501"
        iyz="7.3636E-20"
        izz="0.00024244" />
    </inertial>
    <visual>
      <origin
        xyz="0 0 0"
        rpy="0 0 0" />
      <geometry>
        <mesh
          filename="package://arduinobot_description/meshes/link_1.STL" scale="0.01 0.01 0.01"/>
      </geometry>
      <material
        name="">
        <color
          rgba="0.79216 0.81961 0.93333 1" />
      </material>
    </visual>
    <collision>
      <origin
        xyz="0 0 0"
        rpy="0 0 0" />
      <geometry>
        <mesh
          filename="package://arduinobot_description/meshes/link_1.STL" scale="0.01 0.01 0.01"/>
      </geometry>
    </collision>
  </link>
  <joint
    name="joint_1"
    type="revolute">
    <origin
      xyz="0 0 0.05"
      rpy="0 0 0" />
    <parent
      link="base_link" />
    <child
      link="link_1" />
    <axis
      xyz="0 0 1" />
    <limit
      lower="-1.57"
      upper="1.57"
      effort="0"
      velocity="0" />
  </joint>
  <link
    name="link_2">
    <inertial>
      <origin
        xyz="-0.0024031 -0.2305 -1.2661E-14"
        rpy="0 0 0" />
      <mass
        value="1.5673" />
      <inertia
        ixx="0.012457"
        ixy="-0.00028372"
        ixz="2.8287E-19"
        iyy="0.0017814"
        iyz="2.9045E-18"
        izz="0.013454" />
    </inertial>
    <visual>
      <origin
        xyz="0 0 0"
        rpy="0 0 0" />
      <geometry>
        <mesh
          filename="package://arduinobot_description/meshes/link_2.STL" scale="0.01 0.01 0.01"/>
      </geometry>
      <material
        name="">
        <color
          rgba="0.75294 0.75294 0.75294 1" />
      </material>
    </visual>
    <collision>
      <origin
        xyz="0 0 0"
        rpy="0 0 0" />
      <geometry>
        <mesh
          filename="package://arduinobot_description/meshes/link_2.STL" scale="0.01 0.01 0.01"/>
      </geometry>
    </collision>
  </link>
  <joint
    name="joint_2"
    type="revolute">
    <origin
      xyz="0 0 0.075"
      rpy="-1.5708 0 0" />
    <parent
      link="link_1" />
    <child
      link="link_2" />
    <axis
      xyz="0 0 1" />
    <limit
      lower="0"
      upper="1.57"
      effort="0"
      velocity="0" />
  </joint>
  <link
    name="link_3">
    <inertial>
      <origin
        xyz="0.000235 0.053565 1.5898E-08"
        rpy="0 0 0" />
      <mass
        value="0.25418" />
      <inertia
        ixx="0.00065488"
        ixy="1.2999E-06"
        ixz="-2.9375E-09"
        iyy="0.00020721"
        iyz="3.0298E-14"
        izz="0.00067444" />
    </inertial>
    <visual>
      <origin
        xyz="0 0 0"
        rpy="0 0 0" />
      <geometry>
        <mesh
          filename="package://arduinobot_description/meshes/link_3.STL" scale="0.01 0.01 0.01"/>
      </geometry>
      <material
        name="">
        <color
          rgba="0.75294 0.75294 0.75294 1" />
      </material>
    </visual>
    <collision>
      <origin
        xyz="0 0 0"
        rpy="0 0 0" />
      <geometry>
        <mesh
          filename="package://arduinobot_description/meshes/link_3.STL" scale="0.01 0.01 0.01"/>
      </geometry>
    </collision>
  </link>
  <joint
    name="joint_3"
    type="revolute">
    <origin
      xyz="0 -0.6 0"
      rpy="0 0 -1.5708" />
    <parent
      link="link_2" />
    <child
      link="link_3" />
    <axis
      xyz="0 0 1" />
    <limit
      lower="0"
      upper="1.57"
      effort="0"
      velocity="0" />
  </joint>
  <link
    name="link_4">
    <inertial>
      <origin
        xyz="3.1261E-09 -2.3791E-09 0.24749"
        rpy="0 0 0" />
      <mass
        value="0.1198" />
      <inertia
        ixx="0.0012832"
        ixy="3.0175E-07"
        ixz="-1.0095E-10"
        iyy="0.0012798"
        iyz="-5.5432E-11"
        izz="4.2803E-05" />
    </inertial>
    <visual>
      <origin
        xyz="0 0 0"
        rpy="0 0 0" />
      <geometry>
        <mesh
          filename="package://arduinobot_description/meshes/link_4.STL" scale="0.01 0.01 0.01"/>
      </geometry>
      <material
        name="">
        <color
          rgba="0.75294 0.75294 0.75294 1" />
      </material>
    </visual>
    <collision>
      <origin
        xyz="0 0 0"
        rpy="0 0 0" />
      <geometry>
        <mesh
          filename="package://arduinobot_description/meshes/link_4.STL" scale="0.01 0.01 0.01"/>
      </geometry>
    </collision>
  </link>
  <joint
    name="joint_4"
    type="continuous">
    <origin
      xyz="0 0.096935 0"
      rpy="-1.5708 0 0" />
    <parent
      link="link_3" />
    <child
      link="link_4" />
    <axis
      xyz="0 0 -1" />
  </joint>
  <link
    name="link_5">
    <inertial>
      <origin
        xyz="-0.012354 0.086588 0.0010814"
        rpy="0 0 0" />
      <mass
        value="0.16939" />
      <inertia
        ixx="6.9757E-05"
        ixy="1.0166E-07"
        ixz="2.5517E-06"
        iyy="0.00014204"
        iyz="-9.0142E-09"
        izz="9.8684E-05" />
    </inertial>
    <visual>
      <origin
        xyz="0 0 0"
        rpy="0 0 0" />
      <geometry>
        <mesh
          filename="package://arduinobot_description/meshes/link_5.STL" scale="0.01 0.01 0.01"/>
      </geometry>
      <material
        name="">
        <color
          rgba="0.75294 0.75294 0.75294 1" />
      </material>
    </visual>
    <collision>
      <origin
        xyz="0 0 0"
        rpy="0 0 0" />
      <geometry>
        <mesh
          filename="package://arduinobot_description/meshes/link_5.STL" scale="0.01 0.01 0.01"/>
      </geometry>
    </collision>
  </link>
  <joint
    name="joint_5"
    type="revolute">
    <origin
      xyz="0 0 0.446"
      rpy="1.5708 0 0" />
    <parent
      link="link_4" />
    <child
      link="link_5" />
    <axis
      xyz="0.087156 0 0.99619" />
    <limit
      lower="-1.05"
      upper="1.05"
      effort="0"
      velocity="0" />
  </joint>
  <link
    name="link_6">
    <inertial>
      <origin
        xyz="0.013193 0.00095144 0.048694"
        rpy="0 0 0" />
      <mass
        value="0.45819" />
      <inertia
        ixx="0.00081316"
        ixy="3.3376E-06"
        ixz="-8.6626E-05"
        iyy="0.0007303"
        iyz="-8.9077E-06"
        izz="0.00046173" />
    </inertial>
    <visual>
      <origin
        xyz="0 0 0"
        rpy="0 0 0" />
      <geometry>
        <mesh
          filename="package://arduinobot_description/meshes/link_6.STL" scale="0.01 0.01 0.01"/>
      </geometry>
      <material
        name="">
        <color
          rgba="0.79216 0.81961 0.93333 1" />
      </material>
    </visual>
    <collision>
      <origin
        xyz="0 0 0"
        rpy="0 0 0" />
      <geometry>
        <mesh
          filename="package://arduinobot_description/meshes/link_6.STL" scale="0.01 0.01 0.01"/>
      </geometry>
    </collision>
  </link>
  <joint
    name="joint_6"
    type="continuous">
    <origin
      xyz="0 0.115 0"
      rpy="-1.5708 0 0" />
    <parent
      link="link_5" />
    <child
      link="link_6" />
    <axis
      xyz="0 0 -1" />
  </joint>
  <link
    name="link_7">
    <inertial>
      <origin
        xyz="0.0091853 0.061227 -0.0040459"
        rpy="0 0 0" />
      <mass
        value="0.13579" />
      <inertia
        ixx="0.00019716"
        ixy="-1.6744E-05"
        ixz="-1.0765E-05"
        iyy="0.00013052"
        iyz="-3.2799E-06"
        izz="9.4558E-05" />
    </inertial>
    <visual>
      <origin
        xyz="0 0 0"
        rpy="0 0 0" />
      <geometry>
        <mesh
          filename="package://arduinobot_description/meshes/link_7.STL" scale="0.01 0.01 0.01"/>
      </geometry>
      <material
        name="">
        <color
          rgba="0.79216 0.81961 0.93333 1" />
      </material>
    </visual>
    <collision>
      <origin
        xyz="0 0 0"
        rpy="0 0 0" />
      <geometry>
        <mesh
          filename="package://arduinobot_description/meshes/link_7.STL" scale="0.01 0.01 0.01"/>
      </geometry>
    </collision>
  </link>
  <joint
    name="joint_7"
    type="revolute">
    <origin
      xyz="-0.026356 -0.0039513 0.03015"
      rpy="1.5708 0 0" />
    <parent
      link="link_6" />
    <child
      link="link_7" />
    <axis
      xyz="-0.087156 0 -0.99619" />
    <limit
      lower="0"
      upper="1.05"
      effort="0"
      velocity="0" />
  </joint>
</robot>